Workbook

Sheet Leia-me
A1: Tabela de-para CINE Brasil x CBO 2002 (validada com CAGED e INEP 2024)
A2: Projeto Integrador II · Fatec Santana de Parnaíba · Ciência de Dados
A4: Objetivo
A5: Ligar área do curso (CINE Brasil, usada pelo INEP no Censo da Educação Superior) à ocupação do emprego (CBO 2002, usada no Novo CAGED e na RAIS).
A7: Como usar no Power BI
A8: 1. A busca em cascata é feita pelo script scripts/04_dim_cbo.py, que gera dados_tratados/dCBO.csv com todas as ocupações da CBO já classificadas.
A9: 2. Ordem da busca: 4 dígitos, depois 3, 2 e 1 (do mais específico ao mais geral). No Power BI, relacionar fAdmissoes[cbo2002ocupacao] com dCBO[cbo_codigo].
A10: 3. Índice de descompasso: só tipo_vinculo = Principal e admissões com superior completo ou mais (graus 9, 10, 11 e 80). Formados em ocupações dos grandes grupos 4 a 9 contam como sobrequalificação.
A12: Legenda
A13: Células com fundo amarelo são editáveis: revisar código, área e confiança.
A14: Coluna area_nome é fórmula (busca na aba CINE_Areas); não editar.
A15: Confiança: Alta = área confirmada pelo nome do curso no INEP 2024; Média = mapeamento usual, com exceções. A coluna fonte registra a evidência usada.
... A20: Uma ocupação pode receber formados de mais de uma área (ex.: Engenheiro de produção e Administração). Aqui cada ocupação tem uma área principal; essa simplificação deve ser citada como limitação no relatório.

Sheet CINE_Areas
A1: area_codigo | B1: area_nome
A2: 00 | B2: Programas básicos
A3: 01 | B3: Educação
A4: 02 | B4: Artes e humanidades
A5: 03 | B5: Ciências sociais, comunicação e informação
A6: 04 | B6: Negócios, administração e direito
A7: 05 | B7: Ciências naturais, matemática e estatística
A8: 06 | B8: Computação e Tecnologias da Informação e Comunicação (TIC)
A9: 07 | B9: Engenharia, produção e construção
A10: 08 | B10: Agricultura, silvicultura, pesca e veterinária
A11: 09 | B11: Saúde e bem-estar
A12: 10 | B12: Serviços

Sheet DePara_CBO_CINE
A1: cbo_codigo | B1: cbo_nivel | C1: cbo_descricao | D1: area_codigo | E1: area_nome | F1: tipo_vinculo | G1: confianca | H1: observacao | I1: fonte
A2: 2122 | B2: Família | C2: Engenheiros em computação | D2: 06 | E2: =IFERROR(INDEX(CINE_Areas!$B$2:$B$12,MATCH(D2,CINE_Areas!$A$2:$A$12,0)),"Código inválido") | F2: Principal | G2: Média | H2: Pode receber formados de Engenharia (07) | I2: CBO 2002 + CINE Brasil (rascunho revisado)
A3: 2123 | B3: Família | C3: Administradores de tecnologia da informação | D3: 06 | E3: =IFERROR(INDEX(CINE_Areas!$B$2:$B$12,MATCH(D3,CINE_Areas!$A$2:$A$12,0)),"Código inválido") | F3: Principal | G3: Média | I3: CBO 2002 + CINE Brasil (rascunho revisado)
A4: 2124 | B4: Família | C4: Analistas de tecnologia da informação | D4: 06 | E4: =IFERROR(INDEX(CINE_Areas!$B$2:$B$12,MATCH(D4,CINE_Areas!$A$2:$A$12,0)),"Código inválido") | F4: Principal | G4: Alta | H4: Família central para cursos de TI e tecnólogos Fatec | I4: INEP 2024: ADS e Ciência de Dados em 06
A5: 3171 | B5: Família | C5: Técnicos de desenvolvimento de sistemas e aplicações | D5: 06 | E5: =IFERROR(INDEX(CINE_Areas!$B$2:$B$12,MATCH(D5,CINE_Areas!$A$2:$A$12,0)),"Código inválido") | F5: Principal | G5: Média | H5: Programador: destino típico do tecnólogo em Análise e Desenvolvimento de Sistemas | I5: INEP 2024: ADS em 06
A6: 3172 | B6: Família | C6: Técnicos em operação e monitoração de computadores | D6: 06 | E6: =IFERROR(INDEX(CINE_Areas!$B$2:$B$12,MATCH(D6,CINE_Areas!$A$2:$A$12,0)),"Código inválido") | F6: Secundário | G6: Média | H6: Grupo 3 (técnico) | I6: INEP 2024: ADS e Sistemas para Internet em 06
A7: 2111 | B7: Família | C7: Profissionais da matemática | D7: 05 | E7: =IFERROR(INDEX(CINE_Areas!$B$2:$B$12,MATCH(D7,CINE_Areas!$A$2:$A$12,0)),"Código inválido") | F7: Principal | G7: Média | I7: CBO 2002 + CINE Brasil (rascunho revisado)
A8: 2112 | B8: Família | C8: Profissionais de estatística | D8: 05 | E8: =IFERROR(INDEX(CINE_Areas!$B$2:$B$12,MATCH(D8,CINE_Areas!$A$2:$A$12,0)),"Código inválido") | F8: Principal | G8: Média | H8: Ciência de Dados pode cair em 05 ou 06 conforme CINE do curso | I8: CBO 2002 + CINE Brasil (rascunho revisado)
A9: 2131 | B9: Família | C9: Físicos | D9: 05 | E9: =IFERROR(INDEX(CINE_Areas!$B$2:$B$12,MATCH(D9,CINE_Areas!$A$2:$A$12,0)),"Código inválido") | F9: Principal | G9: Média | I9: CBO 2002 + CINE Brasil (rascunho revisado)
A10: 2132 | B10: Família | C10: Químicos | D10: 05 | E10: =IFERROR(INDEX(CINE_Areas!$B$2:$B$12,MATCH(D10,CINE_Areas!$A$2:$A$12,0)),"Código inválido") | F10: Principal | G10: Média | I10: CBO 2002 + CINE Brasil (rascunho revisado)
A11: 2134 | B11: Família | C11: Geólogos e geofísicos | D11: 05 | E11: =IFERROR(INDEX(CINE_Areas!$B$2:$B$12,MATCH(D11,CINE_Areas!$A$2:$A$12,0)),"Código inválido") | F11: Principal | G11: Média | I11: CINE: Geologia em 05
A12: 2211 | B12: Família | C12: Biólogos e afins | D12: 05 | E12: =IFERROR(INDEX(CINE_Areas!$B$2:$B$12,MATCH(D12,CINE_Areas!$A$2:$A$12,0)),"Código inválido") | F12: Principal | G12: Média | I12: CBO 2002 + CINE Brasil (rascunho revisado)
A13: 2140 | B13: Família | C13: Engenheiros ambientais e afins | D13: 07 | E13: =IFERROR(INDEX(CINE_Areas!$B$2:$B$12,MATCH(D13,CINE_Areas!$A$2:$A$12,0)),"Código inválido") | F13: Principal | G13: Média | I13: INEP 2024: Engenharia Ambiental em 07
A14: 2141 | B14: Família | C14: Arquitetos e urbanistas | D14: 07 | E14: =IFERROR(INDEX(CINE_Areas!$B$2:$B$12,MATCH(D14,CINE_Areas!$A$2:$A$12,0)),"Código inválido") | F14: Principal | G14: Média | I14: CBO 2002 + CINE Brasil (rascunho revisado)
A15: 2142 | B15: Família | C15: Engenheiros civis e afins | D15: 07 | E15: =IFERROR(INDEX(CINE_Areas!$B$2:$B$12,MATCH(D15,CINE_Areas!$A$2:$A$12,0)),"Código inválido") | F15: Principal | G15: Média | I15: CBO 2002 + CINE Brasil (rascunho revisado)
A16: 2143 | B16: Família | C16: Engenheiros eletroeletrônicos e afins | D16: 07 | E16: =IFERROR(INDEX(CINE_Areas!$B$2:$B$12,MATCH(D16,CINE_Areas!$A$2:$A$12,0)),"Código inválido") | F16: Principal | G16: Média | I16: CBO 2002 + CINE Brasil (rascunho revisado)
A17: 2144 | B17: Família | C17: Engenheiros mecânicos | D17: 07 | E17: =IFERROR(INDEX(CINE_Areas!$B$2:$B$12,MATCH(D17,CINE_Areas!$A$2:$A$12,0)),"Código inválido") | F17: Principal | G17: Média | I17: CBO 2002 + CINE Brasil (rascunho revisado)
A18: 2145 | B18: Família | C18: Engenheiros químicos | D18: 07 | E18: =IFERROR(INDEX(CINE_Areas!$B$2:$B$12,MATCH(D18,CINE_Areas!$A$2:$A$12,0)),"Código inválido") | F18: Principal | G18: Média | I18: CBO 2002 + CINE Brasil (rascunho revisado)
A19: 2146 | B19: Família | C19: Engenheiros metalurgistas e de materiais | D19: 07 | E19: =IFERROR(INDEX(CINE_Areas!$B$2:$B$12,MATCH(D19,CINE_Areas!$A$2:$A$12,0)),"Código inválido") | F19: Principal | G19: Média | I19: CBO 2002 + CINE Brasil (rascunho revisado)
A20: 2149 | B20: Família | C20: Engenheiros de produção, qualidade e segurança | D20: 07 | E20: =IFERROR(INDEX(CINE_Areas!$B$2:$B$12,MATCH(D20,CINE_Areas!$A$2:$A$12,0)),"Código inválido") | F20: Principal | G20: Média | H20: Formados em Administração (04) também ocupam | I20: CBO 2002 + CINE Brasil (rascunho revisado)
A21: 2221 | B21: Família | C21: Engenheiros agrossilvipecuários | D21: 08 | E21: =IFERROR(INDEX(CINE_Areas!$B$2:$B$12,MATCH(D21,CINE_Areas!$A$2:$A$12,0)),"Código inválido") | F21: Principal | G21: Média | I21: CBO 2002 + CINE Brasil (rascunho revisado)
A22: 2233 | B22: Família | C22: Médicos veterinários | D22: 08 | E22: =IFERROR(INDEX(CINE_Areas!$B$2:$B$12,MATCH(D22,CINE_Areas!$A$2:$A$12,0)),"Código inválido") | F22: Principal | G22: Alta | H22: CINE classifica Veterinária em 08 | I22: INEP 2024: Medicina Veterinária em 08
A23: 2212 | B23: Família | C23: Biomédicos | D23: 09 | E23: =IFERROR(INDEX(CINE_Areas!$B$2:$B$12,MATCH(D23,CINE_Areas!$A$2:$A$12,0)),"Código inválido") | F23: Principal | G23: Alta | I23: INEP 2024: Biomedicina em 09
A24: 2232 | B24: Família | C24: Cirurgiões-dentistas | D24: 09 | E24: =IFERROR(INDEX(CINE_Areas!$B$2:$B$12,MATCH(D24,CINE_Areas!$A$2:$A$12,0)),"Código inválido") | F24: Principal | G24: Média | I24: CBO 2002 + CINE Brasil (rascunho revisado)
A25: 2234 | B25: Família | C25: Farmacêuticos | D25: 09 | E25: =IFERROR(INDEX(CINE_Areas!$B$2:$B$12,MATCH(D25,CINE_Areas!$A$2:$A$12,0)),"Código inválido") | F25: Principal | G25: Média | I25: CBO 2002 + CINE Brasil (rascunho revisado)
A26: 2235 | B26: Família | C26: Enfermeiros e afins | D26: 09 | E26: =IFERROR(INDEX(CINE_Areas!$B$2:$B$12,MATCH(D26,CINE_Areas!$A$2:$A$12,0)),"Código inválido") | F26: Principal | G26: Média | I26: CBO 2002 + CINE Brasil (rascunho revisado)
A27: 2236 | B27: Família | C27: Fisioterapeutas | D27: 09 | E27: =IFERROR(INDEX(CINE_Areas!$B$2:$B$12,MATCH(D27,CINE_Areas!$A$2:$A$12,0)),"Código inválido") | F27: Principal | G27: Média | I27: CBO 2002 + CINE Brasil (rascunho revisado)
A28: 2237 | B28: Família | C28: Nutricionistas | D28: 09 | E28: =IFERROR(INDEX(CINE_Areas!$B$2:$B$12,MATCH(D28,CINE_Areas!$A$2:$A$12,0)),"Código inválido") | F28: Principal | G28: Média | I28: CBO 2002 + CINE Brasil (rascunho revisado)
A29: 2238 | B29: Família | C29: Fonoaudiólogos | D29: 09 | E29: =IFERROR(INDEX(CINE_Areas!$B$2:$B$12,MATCH(D29,CINE_Areas!$A$2:$A$12,0)),"Código inválido") | F29: Principal | G29: Média | I29: CBO 2002 + CINE Brasil (rascunho revisado)
A30: 2251 | B30: Família | C30: Médicos clínicos | D30: 09 | E30: =IFERROR(INDEX(CINE_Areas!$B$2:$B$12,MATCH(D30,CINE_Areas!$A$2:$A$12,0)),"Código inválido") | F30: Principal | G30: Média | I30: CBO 2002 + CINE Brasil (rascunho revisado)
A31: 2252 | B31: Família | C31: Médicos em especialidades cirúrgicas | D31: 09 | E31: =IFERROR(INDEX(CINE_Areas!$B$2:$B$12,MATCH(D31,CINE_Areas!$A$2:$A$12,0)),"Código inválido") | F31: Principal | G31: Média | I31: CBO 2002 + CINE Brasil (rascunho revisado)
A32: 2253 | B32: Família | C32: Médicos em medicina diagnóstica e terapêutica | D32: 09 | E32: =IFERROR(INDEX(CINE_Areas!$B$2:$B$12,MATCH(D32,CINE_Areas!$A$2:$A$12,0)),"Código inválido") | F32: Principal | G32: Média | I32: CBO 2002 + CINE Brasil (rascunho revisado)
A33: 2515 | B33: Família | C33: Psicólogos e psicanalistas | D33: 03 | E33: =IFERROR(INDEX(CINE_Areas!$B$2:$B$12,MATCH(D33,CINE_Areas!$A$2:$A$12,0)),"Código inválido") | F33: Principal | G33: Alta | H33: INEP coloca Psicologia em 03 | I33: INEP 2024: Psicologia em 03
A34: 2516 | B34: Família | C34: Assistentes sociais e economistas domésticos | D34: 09 | E34: =IFERROR(INDEX(CINE_Areas!$B$2:$B$12,MATCH(D34,CINE_Areas!$A$2:$A$12,0)),"Código inválido") | F34: Principal | G34: Alta | H34: CINE coloca Serviço Social em 09 | I34: INEP 2024: Serviço Social em 09
A35: 2241 | B35: Família | C35: Profissionais da educação física | D35: 09 | E35: =IFERROR(INDEX(CINE_Areas!$B$2:$B$12,MATCH(D35,CINE_Areas!$A$2:$A$12,0)),"Código inválido") | F35: Principal | G35: Média | H35: Bacharelado em 09; licenciatura em Educação Física cai em 01 | I35: INEP 2024: Educação Física (bacharelado) em 09
A36: 23 | B36: Subgrupo principal | C36: Profissionais do ensino (todas as famílias 23xx) | D36: 01 | E36: =IFERROR(INDEX(CINE_Areas!$B$2:$B$12,MATCH(D36,CINE_Areas!$A$2:$A$12,0)),"Código inválido") | F36: Principal | G36: Alta | H36: Mapear no nível de 2 dígitos | I36: CBO 2002 + CINE Brasil (rascunho revisado)
A37: 24 | B37: Subgrupo principal | C37: Profissionais das ciências jurídicas (24xx) | D37: 04 | E37: =IFERROR(INDEX(CINE_Areas!$B$2:$B$12,MATCH(D37,CINE_Areas!$A$2:$A$12,0)),"Código inválido") | F37: Principal | G37: Alta | H37: Direito está em 04 na CINE | I37: CBO 2002 + CINE Brasil (rascunho revisado)
A38: 2521 | B38: Família | C38: Administradores | D38: 04 | E38: =IFERROR(INDEX(CINE_Areas!$B$2:$B$12,MATCH(D38,CINE_Areas!$A$2:$A$12,0)),"Código inválido") | F38: Principal | G38: Média | I38: CBO 2002 + CINE Brasil (rascunho revisado)
A39: 2522 | B39: Família | C39: Contadores e afins | D39: 04 | E39: =IFERROR(INDEX(CINE_Areas!$B$2:$B$12,MATCH(D39,CINE_Areas!$A$2:$A$12,0)),"Código inválido") | F39: Principal | G39: Média | I39: CBO 2002 + CINE Brasil (rascunho revisado)
A40: 2523 | B40: Família | C40: Secretárias(os) executivas(os) e afins | D40: 04 | E40: =IFERROR(INDEX(CINE_Areas!$B$2:$B$12,MATCH(D40,CINE_Areas!$A$2:$A$12,0)),"Código inválido") | F40: Principal | G40: Alta | I40: INEP 2024: Secretariado em 04
...

Sheet Escolaridade_CAGED
A1: codigo_graudeinstrucao | B1: descricao | C1: grupo_analise
A2: 1 | B2: Analfabeto | C2: Fundamental ou menos
A3: 2 | B3: Até 5º ano incompleto | C3: Fundamental ou menos
A4: 3 | B4: 5º ano completo | C4: Fundamental ou menos
A5: 4 | B5: 6º ao 9º ano incompleto | C5: Fundamental ou menos
A6: 5 | B6: Fundamental completo | C6: Fundamental ou menos
A7: 6 | B7: Médio incompleto | C7: Fundamental ou menos
A8: 7 | B8: Médio completo | C8: Médio
A9: 8 | B9: Superior incompleto | C9: Superior incompleto
A10: 9 | B10: Superior completo | C10: Superior
A11: 10 | B11: Mestrado | C11: Superior
A12: 11 | B12: Doutorado | C12: Superior
... A14: 99 | B14: Não identificado | C14: Não identificado

Sheet Resumo
A1: area_codigo | B1: area_nome | C1: ocupacoes_mapeadas | D1: principal | E1: a_verificar
A2: 00 | B2: =CINE_Areas!B2 | C2: =COUNTIFS(DePara_CBO_CINE!$D$2:$D$80,A2) | D2: =COUNTIFS(DePara_CBO_CINE!$D$2:$D$80,A2,DePara_CBO_CINE!$F$2:$F$80,"Principal") | E2: =COUNTIFS(DePara_CBO_CINE!$D$2:$D$80,A2,DePara_CBO_CINE!$G$2:$G$80,"Verificar")
A3: 01 | B3: =CINE_Areas!B3 | C3: =COUNTIFS(DePara_CBO_CINE!$D$2:$D$80,A3) | D3: =COUNTIFS(DePara_CBO_CINE!$D$2:$D$80,A3,DePara_CBO_CINE!$F$2:$F$80,"Principal") | E3: =COUNTIFS(DePara_CBO_CINE!$D$2:$D$80,A3,DePara_CBO_CINE!$G$2:$G$80,"Verificar")
A4: 02 | B4: =CINE_Areas!B4 | C4: =COUNTIFS(DePara_CBO_CINE!$D$2:$D$80,A4) | D4: =COUNTIFS(DePara_CBO_CINE!$D$2:$D$80,A4,DePara_CBO_CINE!$F$2:$F$80,"Principal") | E4: =COUNTIFS(DePara_CBO_CINE!$D$2:$D$80,A4,DePara_CBO_CINE!$G$2:$G$80,"Verificar")
A5: 03 | B5: =CINE_Areas!B5 | C5: =COUNTIFS(DePara_CBO_CINE!$D$2:$D$80,A5) | D5: =COUNTIFS(DePara_CBO_CINE!$D$2:$D$80,A5,DePara_CBO_CINE!$F$2:$F$80,"Principal") | E5: =COUNTIFS(DePara_CBO_CINE!$D$2:$D$80,A5,DePara_CBO_CINE!$G$2:$G$80,"Verificar")
A6: 04 | B6: =CINE_Areas!B6 | C6: =COUNTIFS(DePara_CBO_CINE!$D$2:$D$80,A6) | D6: =COUNTIFS(DePara_CBO_CINE!$D$2:$D$80,A6,DePara_CBO_CINE!$F$2:$F$80,"Principal") | E6: =COUNTIFS(DePara_CBO_CINE!$D$2:$D$80,A6,DePara_CBO_CINE!$G$2:$G$80,"Verificar")
A7: 05 | B7: =CINE_Areas!B7 | C7: =COUNTIFS(DePara_CBO_CINE!$D$2:$D$80,A7) | D7: =COUNTIFS(DePara_CBO_CINE!$D$2:$D$80,A7,DePara_CBO_CINE!$F$2:$F$80,"Principal") | E7: =COUNTIFS(DePara_CBO_CINE!$D$2:$D$80,A7,DePara_CBO_CINE!$G$2:$G$80,"Verificar")
A8: 06 | B8: =CINE_Areas!B8 | C8: =COUNTIFS(DePara_CBO_CINE!$D$2:$D$80,A8) | D8: =COUNTIFS(DePara_CBO_CINE!$D$2:$D$80,A8,DePara_CBO_CINE!$F$2:$F$80,"Principal") | E8: =COUNTIFS(DePara_CBO_CINE!$D$2:$D$80,A8,DePara_CBO_CINE!$G$2:$G$80,"Verificar")
A9: 07 | B9: =CINE_Areas!B9 | C9: =COUNTIFS(DePara_CBO_CINE!$D$2:$D$80,A9) | D9: =COUNTIFS(DePara_CBO_CINE!$D$2:$D$80,A9,DePara_CBO_CINE!$F$2:$F$80,"Principal") | E9: =COUNTIFS(DePara_CBO_CINE!$D$2:$D$80,A9,DePara_CBO_CINE!$G$2:$G$80,"Verificar")
A10: 08 | B10: =CINE_Areas!B10 | C10: =COUNTIFS(DePara_CBO_CINE!$D$2:$D$80,A10) | D10: =COUNTIFS(DePara_CBO_CINE!$D$2:$D$80,A10,DePara_CBO_CINE!$F$2:$F$80,"Principal") | E10: =COUNTIFS(DePara_CBO_CINE!$D$2:$D$80,A10,DePara_CBO_CINE!$G$2:$G$80,"Verificar")
A11: 09 | B11: =CINE_Areas!B11 | C11: =COUNTIFS(DePara_CBO_CINE!$D$2:$D$80,A11) | D11: =COUNTIFS(DePara_CBO_CINE!$D$2:$D$80,A11,DePara_CBO_CINE!$F$2:$F$80,"Principal") | E11: =COUNTIFS(DePara_CBO_CINE!$D$2:$D$80,A11,DePara_CBO_CINE!$G$2:$G$80,"Verificar")
A12: 10 | B12: =CINE_Areas!B12 | C12: =COUNTIFS(DePara_CBO_CINE!$D$2:$D$80,A12) | D12: =COUNTIFS(DePara_CBO_CINE!$D$2:$D$80,A12,DePara_CBO_CINE!$F$2:$F$80,"Principal") | E12: =COUNTIFS(DePara_CBO_CINE!$D$2:$D$80,A12,DePara_CBO_CINE!$G$2:$G$80,"Verificar")
B13: Total | C13: =SUM(C2:C12) | D13: =SUM(D2:D12) | E13: =SUM(E2:E12)
A15: Área 00 (Programas básicos) não tem ocupação associada; zero é esperado.
